Workbook

Sheet Start Here
A1: My Brand — Monthly MIS
A2: Investor-grade P&L, channel P&Ls, working capital and cash. Generated by the d2c-mis skill.
A4: HOW TO USE THIS WORKBOOK
A5: 1. Fill the blue cells on each channel tab once a month, from your dashboards. Hover a line label for what goes there, where to find it, and the common mistake.
A6: 2. Fill brand marketing and fixed costs on the Consolidated P&L tab. Everything else there is a formula that sums the channel tabs.
A7: 3. Fill month-end inventory, receivables, payables and the cash lines on the Cash & Working Capital tab. Closing cash should match your bank.
A8: 4. Look at the Checks tab. Anything marked CHECK is worth a second look before you share.
A9: 5. Enter amounts in the unit shown below, excluding GST on costs (you claim the input credit) and including GST on gross sales (the sheet backs it out).
A10: 6. Blue cells are inputs. Black cells are formulas; do not overwrite them. Green cells are links from other tabs.
A12: SETTINGS
A13: Brand | B13: My Brand
A14: Category archetype | B14: Beauty & personal care
A15: Unit for all amounts | B15: INR lakh
A16: First month | B16: Apr-26
A17: Months in this workbook | B17: 12
A18: Generated on | B18: 2026-09-20
A20: GST RATE BY CHANNEL (edit if your blended rate differs)
A21: Channel | B21: Output GST rate | C21: Note
A22: Website | B22: 0.18 | C22: Blended rate on your net revenue in this channel. Apparel: 5% under ₹1,000 MRP, 12% above. Food: 5/12/18% by product.
A23: Quick Commerce | B23: 0.18 | C23: Blended rate on your net revenue in this channel. Apparel: 5% under ₹1,000 MRP, 12% above. Food: 5/12/18% by product.
A25: PLACEMENT DECISIONS (recorded so anyone reading the MIS knows the convention)
A26: Decision | B26: Chosen | C26: Why it matters
A27: Brand-funded consumer promotions on quick commerce: revenue deduction or marketing cost? | B27: Deduct from net sales before gross margin (investor standard; GM% reads lower) | C27: Moves GM% by 5–6 points in food brands. Investors expect the deduction view; your auditor may prefer marketing. CM3 and EBITDA are identical either way.
A28: Shipping and COD fees you collect from website customers: add to revenue or net against logistics? | B28: Net against logistics cost (keeps GMV clean) | C28: Both are accepted. Netting keeps AOV and GMV comparable with marketplaces that never show this fee.
A30: CHANNELS IN THIS WORKBOOK
A31: Website | B31: Own website
A32: Quick Commerce | B32: Quick commerce
A34: ASK THE SKILL (things it can help you think through)
A35: • Which margin should I quote when an investor asks "what are your margins?"
A36: • My ad platform's RoAS and this sheet's RoAS don't match. Which one is right?
A37: • What goes in COGS this month if I bought stock for the next three months?
A38: • Should Nykaa be a revenue deduction or a cost, and why does it change my gross margin?
A39: • Where do influencer codes, influencer retainers and shoots each go?
A40: • What return rate and RoAS should I expect on COD-heavy orders?
A41: Hover any line label on the other tabs for what goes there. Ask the skill about any line, any ratio, or what an investor would ask. To add a channel later: "add Amazon". Your numbers are kept.

Sheet Consolidated P&L
A1: My Brand — Consolidated P&L
A2: Channel tabs roll up here automatically. Fill only the blue cells (brand marketing, fixed costs, below-EBITDA). INR lakh.
A3: Line item | B3: Where to find it / how to fill | C3: Apr-26 | D3: May-26 | E3: Jun-26 | F3: Jul-26 | G3: Aug-26 | H3: Sep-26 | I3: Oct-26 | J3: Nov-26 | K3: Dec-26 | L3: Jan-27 | M3: Feb-27 | N3: Mar-27 | O3: Total / Avg
A4: REVENUE
A5: Gross sales (GMV) incl. GST | B5: Sum of channel tabs; do not type here. | C5: ='Website'!C5+'Quick Commerce'!C5 | D5: ='Website'!D5+'Quick Commerce'!D5 | E5: ='Website'!E5+'Quick Commerce'!E5 | F5: ='Website'!F5+'Quick Commerce'!F5 | G5: ='Website'!G5+'Quick Commerce'!G5 | H5: ='Website'!H5+'Quick Commerce'!H5 | I5: ='Website'!I5+'Quick Commerce'!I5 | J5: ='Website'!J5+'Quick Commerce'!J5 | ... N5: ='Website'!N5+'Quick Commerce'!N5 | O5: =SUM(C5:N5)
A6: Consumer discounts & coupons | B6: Sum of channel tabs; do not type here. | C6: ='Website'!C6+'Quick Commerce'!C6 | D6: ='Website'!D6+'Quick Commerce'!D6 | E6: ='Website'!E6+'Quick Commerce'!E6 | F6: ='Website'!F6+'Quick Commerce'!F6 | G6: ='Website'!G6+'Quick Commerce'!G6 | H6: ='Website'!H6+'Quick Commerce'!H6 | I6: ='Website'!I6+'Quick Commerce'!I6 | J6: ='Website'!J6+'Quick Commerce'!J6 | ... N6: ='Website'!N6+'Quick Commerce'!N6 | O6: =SUM(C6:N6)
A7: Channel / partner margins (netted channels) | B7: Sum of channel tabs; do not type here. | C7: ='Quick Commerce'!C7 | D7: ='Quick Commerce'!D7 | E7: ='Quick Commerce'!E7 | F7: ='Quick Commerce'!F7 | G7: ='Quick Commerce'!G7 | H7: ='Quick Commerce'!H7 | I7: ='Quick Commerce'!I7 | J7: ='Quick Commerce'!J7 | ... N7: ='Quick Commerce'!N7 | O7: =SUM(C7:N7)
A8: Returns, RTO & cancellations after dispatch | B8: Sum of channel tabs; do not type here. | C8: ='Website'!C7+'Quick Commerce'!C8 | D8: ='Website'!D7+'Quick Commerce'!D8 | E8: ='Website'!E7+'Quick Commerce'!E8 | F8: ='Website'!F7+'Quick Commerce'!F8 | G8: ='Website'!G7+'Quick Commerce'!G8 | H8: ='Website'!H7+'Quick Commerce'!H8 | I8: ='Website'!I7+'Quick Commerce'!I8 | J8: ='Website'!J7+'Quick Commerce'!J8 | ... N8: ='Website'!N7+'Quick Commerce'!N8 | O8: =SUM(C8:N8)
A9: Net revenue before GST | B9: Formula; do not type here. | C9: =C5-C6-C7-C8-0-0-0+0 | D9: =D5-D6-D7-D8-0-0-0+0 | E9: =E5-E6-E7-E8-0-0-0+0 | F9: =F5-F6-F7-F8-0-0-0+0 | G9: =G5-G6-G7-G8-0-0-0+0 | H9: =H5-H6-H7-H8-0-0-0+0 | I9: =I5-I6-I7-I8-0-0-0+0 | J9: =J5-J6-J7-J8-0-0-0+0 | ... N9: =N5-N6-N7-N8-0-0-0+0 | O9: =SUM(C9:N9)
A10: Less: GST (output tax) | B10: Sum of channel tabs; do not type here. | C10: ='Website'!C9+'Quick Commerce'!C10 | D10: ='Website'!D9+'Quick Commerce'!D10 | E10: ='Website'!E9+'Quick Commerce'!E10 | F10: ='Website'!F9+'Quick Commerce'!F10 | G10: ='Website'!G9+'Quick Commerce'!G10 | H10: ='Website'!H9+'Quick Commerce'!H10 | I10: ='Website'!I9+'Quick Commerce'!I10 | J10: ='Website'!J9+'Quick Commerce'!J10 | ... N10: ='Website'!N9+'Quick Commerce'!N10 | O10: =SUM(C10:N10)
A11: NET SALES (post GST) | B11: Formula; do not type here. | C11: =C9-C10 | D11: =D9-D10 | E11: =E9-E10 | F11: =F9-F10 | G11: =G9-G10 | H11: =H9-H10 | I11: =I9-I10 | J11: =J9-J10 | ... N11: =N9-N10 | O11: =SUM(C11:N11)
A12: Consumer promotions funded by brand (deduction) | B12: Sum of channel tabs; do not type here. | C12: ='Quick Commerce'!C12 | D12: ='Quick Commerce'!D12 | E12: ='Quick Commerce'!E12 | F12: ='Quick Commerce'!F12 | G12: ='Quick Commerce'!G12 | H12: ='Quick Commerce'!H12 | I12: ='Quick Commerce'!I12 | J12: ='Quick Commerce'!J12 | ... N12: ='Quick Commerce'!N12 | O12: =SUM(C12:N12)
A13: Net sales after brand-funded promotions | B13: Formula; do not type here. | C13: =C11-C12 | D13: =D11-D12 | E13: =E11-E12 | F13: =F11-F12 | G13: =G11-G12 | H13: =H11-H12 | I13: =I11-I12 | J13: =J11-J12 | ... N13: =N11-N12 | O13: =SUM(C13:N13)
A15: COST OF GOODS
A16: Cost of goods sold (product + conversion + primary packaging) | B16: Sum of channel tabs; do not type here. | C16: ='Website'!C13+'Quick Commerce'!C16 | D16: ='Website'!D13+'Quick Commerce'!D16 | E16: ='Website'!E13+'Quick Commerce'!E16 | F16: ='Website'!F13+'Quick Commerce'!F16 | G16: ='Website'!G13+'Quick Commerce'!G16 | H16: ='Website'!H13+'Quick Commerce'!H16 | I16: ='Website'!I13+'Quick Commerce'!I16 | J16: ='Website'!J13+'Quick Commerce'!J16 | ... N16: ='Website'!N13+'Quick Commerce'!N16 | O16: =SUM(C16:N16)
A17: GROSS MARGIN | B17: Formula; do not type here. | C17: =C13-C16 | D17: =D13-D16 | E17: =E13-E16 | F17: =F13-F16 | G17: =G13-G16 | H17: =H13-H16 | I17: =I13-I16 | J17: =J13-J16 | ... N17: =N13-N16 | O17: =SUM(C17:N17)
A18: Gross margin % | B18: Ratio; do not type here. | C18: =IF(C11=0,"",C17/C11) | D18: =IF(D11=0,"",D17/D11) | E18: =IF(E11=0,"",E17/E11) | F18: =IF(F11=0,"",F17/F11) | G18: =IF(G11=0,"",G17/G11) | H18: =IF(H11=0,"",H17/H11) | I18: =IF(I11=0,"",I17/I11) | J18: =IF(J11=0,"",J17/J11) | ... O18: =IF(O11=0,"",O17/O11)
A20: FULFILMENT & CHANNEL COSTS
A21: Logistics: forward, reverse, RTO & COD charges, secondary packaging | B21: Sum of channel tabs; do not type here. | C21: ='Website'!C18+'Quick Commerce'!C21 | D21: ='Website'!D18+'Quick Commerce'!D21 | E21: ='Website'!E18+'Quick Commerce'!E21 | F21: ='Website'!F18+'Quick Commerce'!F21 | G21: ='Website'!G18+'Quick Commerce'!G21 | H21: ='Website'!H18+'Quick Commerce'!H21 | I21: ='Website'!I18+'Quick Commerce'!I21 | J21: ='Website'!J18+'Quick Commerce'!J21 | ... N21: ='Website'!N18+'Quick Commerce'!N21 | O21: =SUM(C21:N21)
A22: Less: shipping & COD fees collected from customers | B22: Sum of channel tabs; do not type here. | C22: ='Website'!C19 | D22: ='Website'!D19 | E22: ='Website'!E19 | F22: ='Website'!F19 | G22: ='Website'!G19 | H22: ='Website'!H19 | I22: ='Website'!I19 | J22: ='Website'!J19 | ... N22: ='Website'!N19 | O22: =SUM(C22:N22)
A23: Warehousing & operations (rent, staff, packing labour) | B23: Sum of channel tabs; do not type here. | C23: ='Website'!C20+'Quick Commerce'!C22 | D23: ='Website'!D20+'Quick Commerce'!D22 | E23: ='Website'!E20+'Quick Commerce'!E22 | F23: ='Website'!F20+'Quick Commerce'!F22 | G23: ='Website'!G20+'Quick Commerce'!G22 | H23: ='Website'!H20+'Quick Commerce'!H22 | I23: ='Website'!I20+'Quick Commerce'!I22 | J23: ='Website'!J20+'Quick Commerce'!J22 | ... N23: ='Website'!N20+'Quick Commerce'!N22 | O23: =SUM(C23:N23)
A24: Payment gateway charges | B24: Sum of channel tabs; do not type here. | C24: ='Website'!C21 | D24: ='Website'!D21 | E24: ='Website'!E21 | F24: ='Website'!F21 | G24: ='Website'!G21 | H24: ='Website'!H21 | I24: ='Website'!I21 | J24: ='Website'!J21 | ... N24: ='Website'!N21 | O24: =SUM(C24:N24)
A25: CONTRIBUTION MARGIN 1 (CM1) | B25: Formula; do not type here. | C25: =C17-C21+C22-C23-C24-0-0 | D25: =D17-D21+D22-D23-D24-0-0 | E25: =E17-E21+E22-E23-E24-0-0 | F25: =F17-F21+F22-F23-F24-0-0 | G25: =G17-G21+G22-G23-G24-0-0 | H25: =H17-H21+H22-H23-H24-0-0 | I25: =I17-I21+I22-I23-I24-0-0 | J25: =J17-J21+J22-J23-J24-0-0 | ... N25: =N17-N21+N22-N23-N24-0-0 | O25: =SUM(C25:N25)
A26: CM1 % | B26: Ratio; do not type here. | C26: =IF(C11=0,"",C25/C11) | D26: =IF(D11=0,"",D25/D11) | E26: =IF(E11=0,"",E25/E11) | F26: =IF(F11=0,"",F25/F11) | G26: =IF(G11=0,"",G25/G11) | H26: =IF(H11=0,"",H25/H11) | I26: =IF(I11=0,"",I25/I11) | J26: =IF(J11=0,"",J25/J11) | ... O26: =IF(O11=0,"",O25/O11)
A28: MARKETING & SELLING
A29: Performance & channel marketing (all channels) | B29: Sum of channel tabs; do not type here. | C29: ='Website'!C26+'Quick Commerce'!C27 | D29: ='Website'!D26+'Quick Commerce'!D27 | E29: ='Website'!E26+'Quick Commerce'!E27 | F29: ='Website'!F26+'Quick Commerce'!F27 | G29: ='Website'!G26+'Quick Commerce'!G27 | H29: ='Website'!H26+'Quick Commerce'!H27 | I29: ='Website'!I26+'Quick Commerce'!I27 | J29: ='Website'!J26+'Quick Commerce'!J27 | ... N29: ='Website'!N26+'Quick Commerce'!N27 | O29: =SUM(C29:N29)
A30: CONTRIBUTION MARGIN 2 (CM2) | B30: Formula; do not type here. | C30: =C25-C29-0-0-0 | D30: =D25-D29-0-0-0 | E30: =E25-E29-0-0-0 | F30: =F25-F29-0-0-0 | G30: =G25-G29-0-0-0 | H30: =H25-H29-0-0-0 | I30: =I25-I29-0-0-0 | J30: =J25-J29-0-0-0 | ... N30: =N25-N29-0-0-0 | O30: =SUM(C30:N30)
A31: CM2 % | B31: Ratio; do not type here. | C31: =IF(C11=0,"",C30/C11) | D31: =IF(D11=0,"",D30/D11) | E31: =IF(E11=0,"",E30/E11) | F31: =IF(F11=0,"",F30/F11) | G31: =IF(G11=0,"",G30/G11) | H31: =IF(H11=0,"",H30/H11) | I31: =IF(I11=0,"",I30/I11) | J31: =IF(J11=0,"",J30/J11) | ... O31: =IF(O11=0,"",O30/O11)
A32: Brand marketing & content (campaigns, shoots, influencer retainers, PR, agency) | B32: Agency retainers, photoshoots, influencer fees not tied to a sale, PR, brand campaigns. Excl. GST. | O32: =SUM(C32:N32)
A33: CONTRIBUTION MARGIN 3 (CM3) | B33: Formula; do not type here. | C33: =C30-C32 | D33: =D30-D32 | E33: =E30-E32 | F33: =F30-F32 | G33: =G30-G32 | H33: =H30-H32 | I33: =I30-I32 | J33: =J30-J32 | ... N33: =N30-N32 | O33: =SUM(C33:N33)
A34: CM3 % | B34: Ratio; do not type here. | C34: =IF(C11=0,"",C33/C11) | D34: =IF(D11=0,"",D33/D11) | E34: =IF(E11=0,"",E33/E11) | F34: =IF(F11=0,"",F33/F11) | G34: =IF(G11=0,"",G33/G11) | H34: =IF(H11=0,"",H33/H11) | I34: =IF(I11=0,"",I33/I11) | J34: =IF(J11=0,"",J33/J11) | ... O34: =IF(O11=0,"",O33/O11)
A36: FIXED COSTS
A37: People: salaries, contractors, founder pay, employee benefits | B37: Payroll for the month incl. PF/ESI and contractors. Exclude warehouse staff (Logistics) and store staff if entered in the offline channel. | O37: =SUM(C37:N37)
A38: Technology: Shopify, apps, SaaS, domains | B38: Shopify bill, app subscriptions, Zoho/Notion/Slack, hosting. Excl. GST. | O38: =SUM(C38:N38)
A39: Office rent, utilities, travel & admin | B39: Office rent, electricity, internet, travel, meals, insurance, bank charges. | O39: =SUM(C39:N39)
A40: Legal, accounting & professional fees | B40: CA, CS, lawyers, consultants. | O40: =SUM(C40:N40)
A41: Sampling & free product (not campaign-led) | B41: Cost of units given away outside a brand campaign: PR seeding, gifting, trade samples. | O41: =SUM(C41:N41)
A42: Write-offs: expired, damaged, liquidated below cost | B42: Stock written off or sold below cost this month, at cost. | O42: =SUM(C42:N42)
A43: OPERATING EBITDA | B43: Formula; do not type here. | C43: =C33-C37-C38-C39-C40-C41-C42 | D43: =D33-D37-D38-D39-D40-D41-D42 | E43: =E33-E37-E38-E39-E40-E41-E42 | F43: =F33-F37-F38-F39-F40-F41-F42 | G43: =G33-G37-G38-G39-G40-G41-G42 | H43: =H33-H37-H38-H39-H40-H41-H42 | I43: =I33-I37-I38-I39-I40-I41-I42 | J43: =J33-J37-J38-J39-J40-J41-J42 | ... N43: =N33-N37-N38-N39-N40-N41-N42 | O43: =SUM(C43:N43)
A44: Operating EBITDA % | B44: Ratio; do not type here. | C44: =IF(C11=0,"",C43/C11) | D44: =IF(D11=0,"",D43/D11) | E44: =IF(E11=0,"",E43/E11) | F44: =IF(F11=0,"",F43/F11) | G44: =IF(G11=0,"",G43/G11) | H44: =IF(H11=0,"",H43/H11) | I44: =IF(I11=0,"",I43/I11) | J44: =IF(J11=0,"",J43/J11) | ... O44: =IF(O11=0,"",O43/O11)
...

Sheet Website
A1: Website — channel P&L
A2: Own website. Blue cells are yours to fill each month, in INR lakh. Hover a label for guidance.
A3: Line item | B3: Where to find it / how to fill | C3: Apr-26 | D3: May-26 | E3: Jun-26 | F3: Jul-26 | G3: Aug-26 | H3: Sep-26 | I3: Oct-26 | J3: Nov-26 | K3: Dec-26 | L3: Jan-27 | M3: Feb-27 | N3: Mar-27 | O3: Total / Avg
A4: REVENUE
A5: Gross sales (GMV) incl. GST | B5: Shopify › Analytics › Gross sales (before discounts, returns and shipping). Woo/Magento: sum of order value incl. GST. | O5: =SUM(C5:N5)
A6: Consumer discounts & coupons | B6: Shopify › Analytics › Discounts. | O6: =SUM(C6:N6)
A7: Returns, RTO & cancellations after dispatch | B7: Shopify › Analytics › Returns, plus RTO value from your courier or Shiprocket RTO report. | O7: =SUM(C7:N7)
A8: Net revenue before GST | B8: Formula; do not type here. | C8: =C5-C6-0-C7-0-0-0+0 | D8: =D5-D6-0-D7-0-0-0+0 | E8: =E5-E6-0-E7-0-0-0+0 | F8: =F5-F6-0-F7-0-0-0+0 | G8: =G5-G6-0-G7-0-0-0+0 | H8: =H5-H6-0-H7-0-0-0+0 | I8: =I5-I6-0-I7-0-0-0+0 | J8: =J5-J6-0-J7-0-0-0+0 | ... N8: =N5-N6-0-N7-0-0-0+0 | O8: =SUM(C8:N8)
A9: Less: GST (output tax) | B9: Formula; do not type here. | C9: =C8-C8/(1+'Start Here'!$B$22) | D9: =D8-D8/(1+'Start Here'!$B$22) | E9: =E8-E8/(1+'Start Here'!$B$22) | F9: =F8-F8/(1+'Start Here'!$B$22) | G9: =G8-G8/(1+'Start Here'!$B$22) | H9: =H8-H8/(1+'Start Here'!$B$22) | I9: =I8-I8/(1+'Start Here'!$B$22) | J9: =J8-J8/(1+'Start Here'!$B$22) | ... N9: =N8-N8/(1+'Start Here'!$B$22) | O9: =SUM(C9:N9)
A10: NET SALES (post GST) | B10: Formula; do not type here. | C10: =C8-C9 | D10: =D8-D9 | E10: =E8-E9 | F10: =F8-F9 | G10: =G8-G9 | H10: =H8-H9 | I10: =I8-I9 | J10: =J8-J9 | ... N10: =N8-N9 | O10: =SUM(C10:N10)
A12: COST OF GOODS
A13: Cost of goods sold (product + conversion + primary packaging) | B13: Contract-manufactured: product cost + primary packaging per unit × units sold this month. Include the cost of testers and samples given away. | O13: =SUM(C13:N13)
A14: GROSS MARGIN | B14: Formula; do not type here. | C14: =C10-C13 | D14: =D10-D13 | E14: =E10-E13 | F14: =F10-F13 | G14: =G10-G13 | H14: =H10-H13 | I14: =I10-I13 | J14: =J10-J13 | ... N14: =N10-N13 | O14: =SUM(C14:N14)
A15: Gross margin % | B15: Ratio; do not type here. | C15: =IF(C10=0,"",C14/C10) | D15: =IF(D10=0,"",D14/D10) | E15: =IF(E10=0,"",E14/E10) | F15: =IF(F10=0,"",F14/F10) | G15: =IF(G10=0,"",G14/G10) | H15: =IF(H10=0,"",H14/H10) | I15: =IF(I10=0,"",I14/I10) | J15: =IF(J10=0,"",J14/J10) | ... O15: =IF(O10=0,"",O14/O10)
A17: FULFILMENT & CHANNEL COSTS
A18: Logistics: forward, reverse, RTO & COD charges, secondary packaging | B18: Shiprocket / Delhivery / Bluedart invoices for the month excl. GST, plus shipper cartons and fillers. Amazon: FBA fulfilment fee. | O18: =SUM(C18:N18)
A19: Less: shipping & COD fees collected from customers | B19: Shopify › Analytics › Shipping charges, plus COD handling fees charged to customers. Enter as a positive number; the sheet subtracts it. | O19: =SUM(C19:N19)
A20: Warehousing & operations (rent, staff, packing labour) | B20: Warehouse rent, warehouse staff, packing consumables for the month. If shared across channels, split by orders. | O20: =SUM(C20:N20)
A21: Payment gateway charges | B21: Razorpay / PayU / Cashfree statement › fees for the month excl. GST. Typically 1.8–2.2% of prepaid collections. | O21: =SUM(C21:N21)
A22: CONTRIBUTION MARGIN 1 (CM1) | B22: Formula; do not type here. | C22: =C14-C18+C19-C20-C21-0-0 | D22: =D14-D18+D19-D20-D21-0-0 | E22: =E14-E18+E19-E20-E21-0-0 | F22: =F14-F18+F19-F20-F21-0-0 | G22: =G14-G18+G19-G20-G21-0-0 | H22: =H14-H18+H19-H20-H21-0-0 | I22: =I14-I18+I19-I20-I21-0-0 | J22: =J14-J18+J19-J20-J21-0-0 | ... N22: =N14-N18+N19-N20-N21-0-0 | O22: =SUM(C22:N22)
A23: CM1 % | B23: Ratio; do not type here. | C23: =IF(C10=0,"",C22/C10) | D23: =IF(D10=0,"",D22/D10) | E23: =IF(E10=0,"",E22/E10) | F23: =IF(F10=0,"",F22/F10) | G23: =IF(G10=0,"",G22/G10) | H23: =IF(H10=0,"",H22/H10) | I23: =IF(I10=0,"",I22/I10) | J23: =IF(J10=0,"",J22/J10) | ... O23: =IF(O10=0,"",O22/O10)
A25: MARKETING & SELLING
A26: Performance marketing (Meta, Google, affiliates) | B26: Meta Ads Manager and Google Ads billing for the month, excluding GST. Add affiliate and influencer payouts tied to sales. | O26: =SUM(C26:N26)
A27: CONTRIBUTION MARGIN 2 (CM2) | B27: Formula; do not type here. | C27: =C22-C26-0-0-0 | D27: =D22-D26-0-0-0 | E27: =E22-E26-0-0-0 | F27: =F22-F26-0-0-0 | G27: =G22-G26-0-0-0 | H27: =H22-H26-0-0-0 | I27: =I22-I26-0-0-0 | J27: =J22-J26-0-0-0 | ... N27: =N22-N26-0-0-0 | O27: =SUM(C27:N27)
A28: CM2 % | B28: Ratio; do not type here. | C28: =IF(C10=0,"",C27/C10) | D28: =IF(D10=0,"",D27/D10) | E28: =IF(E10=0,"",E27/E10) | F28: =IF(F10=0,"",F27/F10) | G28: =IF(G10=0,"",G27/G10) | H28: =IF(H10=0,"",H27/H10) | I28: =IF(I10=0,"",I27/I10) | J28: =IF(J10=0,"",J27/J10) | ... O28: =IF(O10=0,"",O27/O10)
A30: MEMO
A31: Orders shipped (count) | B31: Shopify › Orders (fulfilled) or marketplace › Orders shipped. Offline / Qcom: units or cases invoiced. | O31: =SUM(C31:N31)
A32: Average order value incl. GST | B32: Formula; do not type here. | C32: =IF(C31=0,"",C5/C31) | D32: =IF(D31=0,"",D5/D31) | E32: =IF(E31=0,"",E5/E31) | F32: =IF(F31=0,"",F5/F31) | G32: =IF(G31=0,"",G5/G31) | H32: =IF(H31=0,"",H5/H31) | I32: =IF(I31=0,"",I5/I31) | J32: =IF(J31=0,"",J5/J31) | ... O32: =IF(O31=0,"",O5/O31)
A33: RoAS (net sales ÷ marketing) | B33: Formula; do not type here. | C33: =IF(C26=0,"",C10/C26) | D33: =IF(D26=0,"",D10/D26) | E33: =IF(E26=0,"",E10/E26) | F33: =IF(F26=0,"",F10/F26) | G33: =IF(G26=0,"",G10/G26) | H33: =IF(H26=0,"",H10/H26) | I33: =IF(I26=0,"",I10/I26) | J33: =IF(J26=0,"",J10/J26) | ... O33: =IF(O26=0,"",O10/O26)
A34: Returns & RTO % of GMV | B34: Ratio; do not type here. | C34: =IF(C5=0,"",(C7+0+0+0)/C5) | D34: =IF(D5=0,"",(D7+0+0+0)/D5) | E34: =IF(E5=0,"",(E7+0+0+0)/E5) | F34: =IF(F5=0,"",(F7+0+0+0)/F5) | G34: =IF(G5=0,"",(G7+0+0+0)/G5) | H34: =IF(H5=0,"",(H7+0+0+0)/H5) | I34: =IF(I5=0,"",(I7+0+0+0)/I5) | J34: =IF(J5=0,"",(J7+0+0+0)/J5) | ... O34: =IF(O5=0,"",(O7+0+0+0)/O5)
A35: Discounts % of GMV | B35: Ratio; do not type here. | C35: =IF(C5=0,"",C6/C5) | D35: =IF(D5=0,"",D6/D5) | E35: =IF(E5=0,"",E6/E5) | F35: =IF(F5=0,"",F6/F5) | G35: =IF(G5=0,"",G6/G5) | H35: =IF(H5=0,"",H6/H5) | I35: =IF(I5=0,"",I6/I5) | J35: =IF(J5=0,"",J6/J5) | ... O35: =IF(O5=0,"",O6/O5)
A36: Marketing % of net sales | B36: Ratio; do not type here. | C36: =IF(C10=0,"",(C26+0)/C10) | D36: =IF(D10=0,"",(D26+0)/D10) | E36: =IF(E10=0,"",(E26+0)/E10) | F36: =IF(F10=0,"",(F26+0)/F10) | G36: =IF(G10=0,"",(G26+0)/G10) | H36: =IF(H10=0,"",(H26+0)/H10) | I36: =IF(I10=0,"",(I26+0)/I10) | J36: =IF(J10=0,"",(J26+0)/J10) | ... O36: =IF(O10=0,"",(O26+0)/O10)
A37: Logistics % of net sales | B37: Ratio; do not type here. | C37: =IF(C10=0,"",(C18-C19+C20)/C10) | D37: =IF(D10=0,"",(D18-D19+D20)/D10) | E37: =IF(E10=0,"",(E18-E19+E20)/E10) | F37: =IF(F10=0,"",(F18-F19+F20)/F10) | G37: =IF(G10=0,"",(G18-G19+G20)/G10) | H37: =IF(H10=0,"",(H18-H19+H20)/H10) | I37: =IF(I10=0,"",(I18-I19+I20)/I10) | J37: =IF(J10=0,"",(J18-J19+J20)/J10) | ... O37: =IF(O10=0,"",(O18-O19+O20)/O10)

Sheet Quick Commerce
A1: Quick Commerce — channel P&L
A2: Quick commerce. Blue cells are yours to fill each month, in INR lakh. Hover a label for guidance.
A3: Line item | B3: Where to find it / how to fill | C3: Apr-26 | D3: May-26 | E3: Jun-26 | F3: Jul-26 | G3: Aug-26 | H3: Sep-26 | I3: Oct-26 | J3: Nov-26 | K3: Dec-26 | L3: Jan-27 | M3: Feb-27 | N3: Mar-27 | O3: Total / Avg
A4: REVENUE
A5: Gross sales (GMV) incl. GST | B5: Partner dashboard › GMV at MRP incl. GST for the month. | O5: =SUM(C5:N5)
A6: Consumer discounts & coupons | B6: Leave blank here if you enter brand-funded promos on the Consumer promotions line. | O6: =SUM(C6:N6)
A7: Quick-commerce partner margin | B7: MRP less your invoice price to the partner, per the trade agreement (typically 25–40%). | O7: =SUM(C7:N7)
A8: Returns, RTO & cancellations after dispatch | B8: Expiry or damage returns reversed on the PO. Usually near zero. | O8: =SUM(C8:N8)
A9: Net revenue before GST | B9: Formula; do not type here. | C9: =C5-C6-C7-C8-0-0-0+0 | D9: =D5-D6-D7-D8-0-0-0+0 | E9: =E5-E6-E7-E8-0-0-0+0 | F9: =F5-F6-F7-F8-0-0-0+0 | G9: =G5-G6-G7-G8-0-0-0+0 | H9: =H5-H6-H7-H8-0-0-0+0 | I9: =I5-I6-I7-I8-0-0-0+0 | J9: =J5-J6-J7-J8-0-0-0+0 | ... N9: =N5-N6-N7-N8-0-0-0+0 | O9: =SUM(C9:N9)
A10: Less: GST (output tax) | B10: Formula; do not type here. | C10: =C9-C9/(1+'Start Here'!$B$23) | D10: =D9-D9/(1+'Start Here'!$B$23) | E10: =E9-E9/(1+'Start Here'!$B$23) | F10: =F9-F9/(1+'Start Here'!$B$23) | G10: =G9-G9/(1+'Start Here'!$B$23) | H10: =H9-H9/(1+'Start Here'!$B$23) | I10: =I9-I9/(1+'Start Here'!$B$23) | J10: =J9-J9/(1+'Start Here'!$B$23) | ... N10: =N9-N9/(1+'Start Here'!$B$23) | O10: =SUM(C10:N10)
A11: NET SALES (post GST) | B11: Formula; do not type here. | C11: =C9-C10 | D11: =D9-D10 | E11: =E9-E10 | F11: =F9-F10 | G11: =G9-G10 | H11: =H9-H10 | I11: =I9-I10 | J11: =J9-J10 | ... N11: =N9-N10 | O11: =SUM(C11:N11)
A12: Consumer promotions funded by brand | B12: Partner's debit note for brand-funded discounts, or dashboard › Promotions › brand share. | O12: =SUM(C12:N12)
A13: Net sales after brand-funded promotions | B13: Formula; do not type here. | C13: =C11-C12 | D13: =D11-D12 | E13: =E11-E12 | F13: =F11-F12 | G13: =G11-G12 | H13: =H11-H12 | I13: =I11-I12 | J13: =J11-J12 | ... N13: =N11-N12 | O13: =SUM(C13:N13)
A15: COST OF GOODS
A16: Cost of goods sold (product + conversion + primary packaging) | B16: Contract-manufactured: product cost + primary packaging per unit × units sold this month. Include the cost of testers and samples given away. | O16: =SUM(C16:N16)
A17: GROSS MARGIN | B17: Formula; do not type here. | C17: =C13-C16 | D17: =D13-D16 | E17: =E13-E16 | F17: =F13-F16 | G17: =G13-G16 | H17: =H13-H16 | I17: =I13-I16 | J17: =J13-J16 | ... N17: =N13-N16 | O17: =SUM(C17:N17)
A18: Gross margin % | B18: Ratio; do not type here. | C18: =IF(C11=0,"",C17/C11) | D18: =IF(D11=0,"",D17/D11) | E18: =IF(E11=0,"",E17/E11) | F18: =IF(F11=0,"",F17/F11) | G18: =IF(G11=0,"",G17/G11) | H18: =IF(H11=0,"",H17/H11) | I18: =IF(I11=0,"",I17/I11) | J18: =IF(J11=0,"",J17/J11) | ... O18: =IF(O11=0,"",O17/O11)
A20: FULFILMENT & CHANNEL COSTS
A21: Logistics: forward, reverse, RTO & COD charges, secondary packaging | B21: Shiprocket / Delhivery / Bluedart invoices for the month excl. GST, plus shipper cartons and fillers. Amazon: FBA fulfilment fee. | O21: =SUM(C21:N21)
A22: Warehousing & operations (rent, staff, packing labour) | B22: Warehouse rent, warehouse staff, packing consumables for the month. If shared across channels, split by orders. | O22: =SUM(C22:N22)
A23: CONTRIBUTION MARGIN 1 (CM1) | B23: Formula; do not type here. | C23: =C17-C21+0-C22-0-0-0 | D23: =D17-D21+0-D22-0-0-0 | E23: =E17-E21+0-E22-0-0-0 | F23: =F17-F21+0-F22-0-0-0 | G23: =G17-G21+0-G22-0-0-0 | H23: =H17-H21+0-H22-0-0-0 | I23: =I17-I21+0-I22-0-0-0 | J23: =J17-J21+0-J22-0-0-0 | ... N23: =N17-N21+0-N22-0-0-0 | O23: =SUM(C23:N23)
A24: CM1 % | B24: Ratio; do not type here. | C24: =IF(C11=0,"",C23/C11) | D24: =IF(D11=0,"",D23/D11) | E24: =IF(E11=0,"",E23/E11) | F24: =IF(F11=0,"",F23/F11) | G24: =IF(G11=0,"",G23/G11) | H24: =IF(H11=0,"",H23/H11) | I24: =IF(I11=0,"",I23/I11) | J24: =IF(J11=0,"",J23/J11) | ... O24: =IF(O11=0,"",O23/O11)
A26: MARKETING & SELLING
A27: Quick-commerce ads (sponsored listings) | B27: Blinkit / Zepto / Instamart brand dashboard › Ads › spend excluding GST. | O27: =SUM(C27:N27)
A28: CONTRIBUTION MARGIN 2 (CM2) | B28: Formula; do not type here. | C28: =C23-C27-0-0-0 | D28: =D23-D27-0-0-0 | E28: =E23-E27-0-0-0 | F28: =F23-F27-0-0-0 | G28: =G23-G27-0-0-0 | H28: =H23-H27-0-0-0 | I28: =I23-I27-0-0-0 | J28: =J23-J27-0-0-0 | ... N28: =N23-N27-0-0-0 | O28: =SUM(C28:N28)
A29: CM2 % | B29: Ratio; do not type here. | C29: =IF(C11=0,"",C28/C11) | D29: =IF(D11=0,"",D28/D11) | E29: =IF(E11=0,"",E28/E11) | F29: =IF(F11=0,"",F28/F11) | G29: =IF(G11=0,"",G28/G11) | H29: =IF(H11=0,"",H28/H11) | I29: =IF(I11=0,"",I28/I11) | J29: =IF(J11=0,"",J28/J11) | ... O29: =IF(O11=0,"",O28/O11)
A31: MEMO
A32: Orders shipped (count) | B32: Shopify › Orders (fulfilled) or marketplace › Orders shipped. Offline / Qcom: units or cases invoiced. | O32: =SUM(C32:N32)
A33: Average order value incl. GST | B33: Formula; do not type here. | C33: =IF(C32=0,"",C5/C32) | D33: =IF(D32=0,"",D5/D32) | E33: =IF(E32=0,"",E5/E32) | F33: =IF(F32=0,"",F5/F32) | G33: =IF(G32=0,"",G5/G32) | H33: =IF(H32=0,"",H5/H32) | I33: =IF(I32=0,"",I5/I32) | J33: =IF(J32=0,"",J5/J32) | ... O33: =IF(O32=0,"",O5/O32)
A34: RoAS (net sales ÷ marketing) | B34: Formula; do not type here. | C34: =IF(C27=0,"",C11/C27) | D34: =IF(D27=0,"",D11/D27) | E34: =IF(E27=0,"",E11/E27) | F34: =IF(F27=0,"",F11/F27) | G34: =IF(G27=0,"",G11/G27) | H34: =IF(H27=0,"",H11/H27) | I34: =IF(I27=0,"",I11/I27) | J34: =IF(J27=0,"",J11/J27) | ... O34: =IF(O27=0,"",O11/O27)
A35: Returns & RTO % of GMV | B35: Ratio; do not type here. | C35: =IF(C5=0,"",(C8+0+0+0)/C5) | D35: =IF(D5=0,"",(D8+0+0+0)/D5) | E35: =IF(E5=0,"",(E8+0+0+0)/E5) | F35: =IF(F5=0,"",(F8+0+0+0)/F5) | G35: =IF(G5=0,"",(G8+0+0+0)/G5) | H35: =IF(H5=0,"",(H8+0+0+0)/H5) | I35: =IF(I5=0,"",(I8+0+0+0)/I5) | J35: =IF(J5=0,"",(J8+0+0+0)/J5) | ... O35: =IF(O5=0,"",(O8+0+0+0)/O5)
A36: Discounts % of GMV | B36: Ratio; do not type here. | C36: =IF(C5=0,"",C6/C5) | D36: =IF(D5=0,"",D6/D5) | E36: =IF(E5=0,"",E6/E5) | F36: =IF(F5=0,"",F6/F5) | G36: =IF(G5=0,"",G6/G5) | H36: =IF(H5=0,"",H6/H5) | I36: =IF(I5=0,"",I6/I5) | J36: =IF(J5=0,"",J6/J5) | ... O36: =IF(O5=0,"",O6/O5)
A37: Marketing % of net sales | B37: Ratio; do not type here. | C37: =IF(C11=0,"",(C27+0)/C11) | D37: =IF(D11=0,"",(D27+0)/D11) | E37: =IF(E11=0,"",(E27+0)/E11) | F37: =IF(F11=0,"",(F27+0)/F11) | G37: =IF(G11=0,"",(G27+0)/G11) | H37: =IF(H11=0,"",(H27+0)/H11) | I37: =IF(I11=0,"",(I27+0)/I11) | J37: =IF(J11=0,"",(J27+0)/J11) | ... O37: =IF(O11=0,"",(O27+0)/O11)
A38: Logistics % of net sales | B38: Ratio; do not type here. | C38: =IF(C11=0,"",(C21-0+C22)/C11) | D38: =IF(D11=0,"",(D21-0+D22)/D11) | E38: =IF(E11=0,"",(E21-0+E22)/E11) | F38: =IF(F11=0,"",(F21-0+F22)/F11) | G38: =IF(G11=0,"",(G21-0+G22)/G11) | H38: =IF(H11=0,"",(H21-0+H22)/H11) | I38: =IF(I11=0,"",(I21-0+I22)/I11) | J38: =IF(J11=0,"",(J21-0+J22)/J11) | ... O38: =IF(O11=0,"",(O21-0+O22)/O11)

Sheet Cash & Working Capital
A1: My Brand — Cash & Working Capital
A2: Closing balances at month end and the cash roll-forward. INR lakh. Closing cash should match your bank statement.
A3: Line item | B3: Where to find it / how to fill | C3: Apr-26 | D3: May-26 | E3: Jun-26 | F3: Jul-26 | G3: Aug-26 | H3: Sep-26 | I3: Oct-26 | J3: Nov-26 | K3: Dec-26 | L3: Jan-27 | M3: Feb-27 | N3: Mar-27 | O3: Total / Avg
A4: WORKING CAPITAL (closing balances at month end)
A5: Inventory at cost (finished goods + raw & packing material + goods in transit) | B5: Stock count or inventory system at month end, valued at cost. Include stock at 3PLs, Amazon FBA, Qcom dark stores that is still yours. | O5: =N5
A6: Receivables (money owed to you by platforms, partners, retailers) | B6: Unsettled marketplace payouts + Qcom / B2B / distributor invoices unpaid + COD remittances pending from couriers. | O6: =N6
A7: Payables (money you owe suppliers, agencies, platforms) | B7: Unpaid supplier, manufacturer, courier, agency and ad-platform invoices at month end. | O7: =N7
A8: NET WORKING CAPITAL | B8: Formula; do not type here. | C8: =C5+C6-C7 | D8: =D5+D6-D7 | E8: =E5+E6-E7 | F8: =F5+F6-F7 | G8: =G5+G6-G7 | H8: =H5+H6-H7 | I8: =I5+I6-I7 | J8: =J5+J6-J7 | ... N8: =N5+N6-N7 | O8: =N8
A9: Inventory days (on COGS) | B9: Formula; do not type here. | C9: =IF('Consolidated P&L'!C16=0,"",C5/'Consolidated P&L'!C16*30) | D9: =IF('Consolidated P&L'!D16=0,"",D5/'Consolidated P&L'!D16*30) | E9: =IF('Consolidated P&L'!E16=0,"",E5/'Consolidated P&L'!E16*30) | F9: =IF('Consolidated P&L'!F16=0,"",F5/'Consolidated P&L'!F16*30) | G9: =IF('Consolidated P&L'!G16=0,"",G5/'Consolidated P&L'!G16*30) | H9: =IF('Consolidated P&L'!H16=0,"",H5/'Consolidated P&L'!H16*30) | I9: =IF('Consolidated P&L'!I16=0,"",I5/'Consolidated P&L'!I16*30) | J9: =IF('Consolidated P&L'!J16=0,"",J5/'Consolidated P&L'!J16*30) | ... N9: =IF('Consolidated P&L'!N16=0,"",N5/'Consolidated P&L'!N16*30) | O9: =N9
A10: Receivable days (on net sales) | B10: Formula; do not type here. | C10: =IF('Consolidated P&L'!C11=0,"",C6/'Consolidated P&L'!C11*30) | D10: =IF('Consolidated P&L'!D11=0,"",D6/'Consolidated P&L'!D11*30) | E10: =IF('Consolidated P&L'!E11=0,"",E6/'Consolidated P&L'!E11*30) | F10: =IF('Consolidated P&L'!F11=0,"",F6/'Consolidated P&L'!F11*30) | G10: =IF('Consolidated P&L'!G11=0,"",G6/'Consolidated P&L'!G11*30) | H10: =IF('Consolidated P&L'!H11=0,"",H6/'Consolidated P&L'!H11*30) | I10: =IF('Consolidated P&L'!I11=0,"",I6/'Consolidated P&L'!I11*30) | J10: =IF('Consolidated P&L'!J11=0,"",J6/'Consolidated P&L'!J11*30) | ... N10: =IF('Consolidated P&L'!N11=0,"",N6/'Consolidated P&L'!N11*30) | O10: =N10
A11: Payable days (on COGS) | B11: Formula; do not type here. | C11: =IF('Consolidated P&L'!C16=0,"",C7/'Consolidated P&L'!C16*30) | D11: =IF('Consolidated P&L'!D16=0,"",D7/'Consolidated P&L'!D16*30) | E11: =IF('Consolidated P&L'!E16=0,"",E7/'Consolidated P&L'!E16*30) | F11: =IF('Consolidated P&L'!F16=0,"",F7/'Consolidated P&L'!F16*30) | G11: =IF('Consolidated P&L'!G16=0,"",G7/'Consolidated P&L'!G16*30) | H11: =IF('Consolidated P&L'!H16=0,"",H7/'Consolidated P&L'!H16*30) | I11: =IF('Consolidated P&L'!I16=0,"",I7/'Consolidated P&L'!I16*30) | J11: =IF('Consolidated P&L'!J16=0,"",J7/'Consolidated P&L'!J16*30) | ... N11: =IF('Consolidated P&L'!N16=0,"",N7/'Consolidated P&L'!N16*30) | O11: =N11
A12: Cash conversion cycle (days) | B12: Formula; do not type here. | C12: =C9+C10-C11 | D12: =D9+D10-D11 | E12: =E9+E10-E11 | F12: =F9+F10-F11 | G12: =G9+G10-G11 | H12: =H9+H10-H11 | I12: =I9+I10-I11 | J12: =J9+J10-J11 | ... N12: =N9+N10-N11 | O12: =N12
A14: CASH FLOW
A15: Opening cash (bank + wallets + FDs) | B15: Bank balances on the 1st. Only the first month is typed; later months roll forward. | D15: =C24 | E15: =D24 | F15: =E24 | G15: =F24 | H15: =G24 | I15: =H24 | J15: =I24 | K15: =J24 | ... N15: =M24 | O15: =N15
A16: Reported EBITDA (from Consolidated P&L) | B16: Linked from another tab; do not type here. | C16: ='Consolidated P&L'!C46 | D16: ='Consolidated P&L'!D46 | E16: ='Consolidated P&L'!E46 | F16: ='Consolidated P&L'!F46 | G16: ='Consolidated P&L'!G46 | H16: ='Consolidated P&L'!H46 | I16: ='Consolidated P&L'!I46 | J16: ='Consolidated P&L'!J46 | ... N16: ='Consolidated P&L'!N46 | O16: =SUM(C16:N16)
A17: Less: increase in working capital | B17: First month is 0 (no prior balance). Later months = this month's NWC less last month's. | C17: 0 | D17: =D8-C8 | E17: =E8-D8 | F17: =F8-E8 | G17: =G8-F8 | H17: =H8-G8 | I17: =I8-H8 | J17: =J8-I8 | K17: =K8-J8 | ... N17: =N8-M8 | O17: =SUM(C17:N17)
A18: Less: capex (equipment, moulds, fit-outs, software builds) | B18: Asset purchases this month. | O18: =SUM(C18:N18)
A19: Less: interest & finance charges (from Consolidated P&L) | B19: Linked from another tab; do not type here. | C19: ='Consolidated P&L'!C50 | D19: ='Consolidated P&L'!D50 | E19: ='Consolidated P&L'!E50 | F19: ='Consolidated P&L'!F50 | G19: ='Consolidated P&L'!G50 | H19: ='Consolidated P&L'!H50 | I19: ='Consolidated P&L'!I50 | J19: ='Consolidated P&L'!J50 | ... N19: ='Consolidated P&L'!N50 | O19: =SUM(C19:N19)
A20: Less: taxes paid (income tax, net GST paid) | B20: Advance tax, TDS deposited, net GST cash outflow. | O20: =SUM(C20:N20)
A21: Add: equity raised | B21: Money received from investors or founders this month. | O21: =SUM(C21:N21)
A22: Add: debt drawn less repaid | B22: Loans, credit lines, venture debt drawn, net of principal repaid. | O22: =SUM(C22:N22)
A23: Other cash movements | B23: Anything else: deposits paid, refunds received, corrections. | O23: =SUM(C23:N23)
A24: CLOSING CASH | B24: Formula; do not type here. | C24: =C15+C16-C17-C18-C19-C20+C21+C22+C23 | D24: =D15+D16-D17-D18-D19-D20+D21+D22+D23 | E24: =E15+E16-E17-E18-E19-E20+E21+E22+E23 | F24: =F15+F16-F17-F18-F19-F20+F21+F22+F23 | G24: =G15+G16-G17-G18-G19-G20+G21+G22+G23 | H24: =H15+H16-H17-H18-H19-H20+H21+H22+H23 | I24: =I15+I16-I17-I18-I19-I20+I21+I22+I23 | J24: =J15+J16-J17-J18-J19-J20+J21+J22+J23 | ... N24: =N15+N16-N17-N18-N19-N20+N21+N22+N23 | O24: =N24
A25: Net burn (negative = cash consumed) | B25: Formula; do not type here. | C25: =C24-C15 | D25: =D24-D15 | E25: =E24-E15 | F25: =F24-F15 | G25: =G24-G15 | H25: =H24-H15 | I25: =I24-I15 | J25: =J24-J15 | ... N25: =N24-N15 | O25: =SUM(C25:N25)
A26: Operating burn (before equity & debt) | B26: Formula; do not type here. | C26: =C25-C21-C22 | D26: =D25-D21-D22 | E26: =E25-E21-E22 | F26: =F25-F21-F22 | G26: =G25-G21-G22 | H26: =H25-H21-H22 | I26: =I25-I21-I22 | J26: =J25-J21-J22 | ... N26: =N25-N21-N22 | O26: =SUM(C26:N26)
A27: Runway (months, on last 3 months' operating burn) | B27: Formula; do not type here. | E27: =IF(AVERAGE(C26:E26)>=0,"",-E24/AVERAGE(C26:E26)) | F27: =IF(AVERAGE(D26:F26)>=0,"",-F24/AVERAGE(D26:F26)) | G27: =IF(AVERAGE(E26:G26)>=0,"",-G24/AVERAGE(E26:G26)) | H27: =IF(AVERAGE(F26:H26)>=0,"",-H24/AVERAGE(F26:H26)) | I27: =IF(AVERAGE(G26:I26)>=0,"",-I24/AVERAGE(G26:I26)) | J27: =IF(AVERAGE(H26:J26)>=0,"",-J24/AVERAGE(H26:J26)) | K27: =IF(AVERAGE(I26:K26)>=0,"",-K24/AVERAGE(I26:K26)) | L27: =IF(AVERAGE(J26:L26)>=0,"",-L24/AVERAGE(J26:L26)) | ... N27: =IF(AVERAGE(L26:N26)>=0,"",-N24/AVERAGE(L26:N26)) | O27: =N27

Sheet Checks
A1: Checks — anything marked CHECK deserves a look before you share this MIS
A2: Bands are for the Beauty & personal care archetype. They are guides, not rules; explain an exception rather than hide it.
A3: Check | B3: Rule | C3: Apr-26 | D3: May-26 | E3: Jun-26 | F3: Jul-26 | G3: Aug-26 | H3: Sep-26 | I3: Oct-26 | J3: Nov-26 | K3: Dec-26 | L3: Jan-27 | M3: Feb-27 | N3: Mar-27
A4: Gross margin % within archetype band | B4: 45%–75% of net sales | C4: =IF('Consolidated P&L'!C11=0,"",IF(AND('Consolidated P&L'!C17/'Consolidated P&L'!C11>=0.45,'Consolidated P&L'!C17/'Consolidated P&L'!C11<=0.75),"OK","CHECK")) | D4: =IF('Consolidated P&L'!D11=0,"",IF(AND('Consolidated P&L'!D17/'Consolidated P&L'!D11>=0.45,'Consolidated P&L'!D17/'Consolidated P&L'!D11<=0.75),"OK","CHECK")) | E4: =IF('Consolidated P&L'!E11=0,"",IF(AND('Consolidated P&L'!E17/'Consolidated P&L'!E11>=0.45,'Consolidated P&L'!E17/'Consolidated P&L'!E11<=0.75),"OK","CHECK")) | F4: =IF('Consolidated P&L'!F11=0,"",IF(AND('Consolidated P&L'!F17/'Consolidated P&L'!F11>=0.45,'Consolidated P&L'!F17/'Consolidated P&L'!F11<=0.75),"OK","CHECK")) | G4: =IF('Consolidated P&L'!G11=0,"",IF(AND('Consolidated P&L'!G17/'Consolidated P&L'!G11>=0.45,'Consolidated P&L'!G17/'Consolidated P&L'!G11<=0.75),"OK","CHECK")) | H4: =IF('Consolidated P&L'!H11=0,"",IF(AND('Consolidated P&L'!H17/'Consolidated P&L'!H11>=0.45,'Consolidated P&L'!H17/'Consolidated P&L'!H11<=0.75),"OK","CHECK")) | I4: =IF('Consolidated P&L'!I11=0,"",IF(AND('Consolidated P&L'!I17/'Consolidated P&L'!I11>=0.45,'Consolidated P&L'!I17/'Consolidated P&L'!I11<=0.75),"OK","CHECK")) | J4: =IF('Consolidated P&L'!J11=0,"",IF(AND('Consolidated P&L'!J17/'Consolidated P&L'!J11>=0.45,'Consolidated P&L'!J17/'Consolidated P&L'!J11<=0.75),"OK","CHECK")) | ... N4: =IF('Consolidated P&L'!N11=0,"",IF(AND('Consolidated P&L'!N17/'Consolidated P&L'!N11>=0.45,'Consolidated P&L'!N17/'Consolidated P&L'!N11<=0.75),"OK","CHECK"))
A5: Returns & RTO % of GMV within band | B5: 0%–15% of GMV | C5: =IF('Consolidated P&L'!C5=0,"",IF(AND(('Consolidated P&L'!C8)/'Consolidated P&L'!C5>=0.0,('Consolidated P&L'!C8)/'Consolidated P&L'!C5<=0.15),"OK","CHECK")) | D5: =IF('Consolidated P&L'!D5=0,"",IF(AND(('Consolidated P&L'!D8)/'Consolidated P&L'!D5>=0.0,('Consolidated P&L'!D8)/'Consolidated P&L'!D5<=0.15),"OK","CHECK")) | E5: =IF('Consolidated P&L'!E5=0,"",IF(AND(('Consolidated P&L'!E8)/'Consolidated P&L'!E5>=0.0,('Consolidated P&L'!E8)/'Consolidated P&L'!E5<=0.15),"OK","CHECK")) | F5: =IF('Consolidated P&L'!F5=0,"",IF(AND(('Consolidated P&L'!F8)/'Consolidated P&L'!F5>=0.0,('Consolidated P&L'!F8)/'Consolidated P&L'!F5<=0.15),"OK","CHECK")) | G5: =IF('Consolidated P&L'!G5=0,"",IF(AND(('Consolidated P&L'!G8)/'Consolidated P&L'!G5>=0.0,('Consolidated P&L'!G8)/'Consolidated P&L'!G5<=0.15),"OK","CHECK")) | H5: =IF('Consolidated P&L'!H5=0,"",IF(AND(('Consolidated P&L'!H8)/'Consolidated P&L'!H5>=0.0,('Consolidated P&L'!H8)/'Consolidated P&L'!H5<=0.15),"OK","CHECK")) | I5: =IF('Consolidated P&L'!I5=0,"",IF(AND(('Consolidated P&L'!I8)/'Consolidated P&L'!I5>=0.0,('Consolidated P&L'!I8)/'Consolidated P&L'!I5<=0.15),"OK","CHECK")) | J5: =IF('Consolidated P&L'!J5=0,"",IF(AND(('Consolidated P&L'!J8)/'Consolidated P&L'!J5>=0.0,('Consolidated P&L'!J8)/'Consolidated P&L'!J5<=0.15),"OK","CHECK")) | ... N5: =IF('Consolidated P&L'!N5=0,"",IF(AND(('Consolidated P&L'!N8)/'Consolidated P&L'!N5>=0.0,('Consolidated P&L'!N8)/'Consolidated P&L'!N5<=0.15),"OK","CHECK"))
A6: Logistics % of net sales within band | B6: 5%–15% | C6: =IF('Consolidated P&L'!C11=0,"",IF(AND(('Consolidated P&L'!C21+'Consolidated P&L'!C23)/'Consolidated P&L'!C11>=0.05,('Consolidated P&L'!C21+'Consolidated P&L'!C23)/'Consolidated P&L'!C11<=0.15),"OK","CHECK")) | D6: =IF('Consolidated P&L'!D11=0,"",IF(AND(('Consolidated P&L'!D21+'Consolidated P&L'!D23)/'Consolidated P&L'!D11>=0.05,('Consolidated P&L'!D21+'Consolidated P&L'!D23)/'Consolidated P&L'!D11<=0.15),"OK","CHECK")) | E6: =IF('Consolidated P&L'!E11=0,"",IF(AND(('Consolidated P&L'!E21+'Consolidated P&L'!E23)/'Consolidated P&L'!E11>=0.05,('Consolidated P&L'!E21+'Consolidated P&L'!E23)/'Consolidated P&L'!E11<=0.15),"OK","CHECK")) | F6: =IF('Consolidated P&L'!F11=0,"",IF(AND(('Consolidated P&L'!F21+'Consolidated P&L'!F23)/'Consolidated P&L'!F11>=0.05,('Consolidated P&L'!F21+'Consolidated P&L'!F23)/'Consolidated P&L'!F11<=0.15),"OK","CHECK")) | G6: =IF('Consolidated P&L'!G11=0,"",IF(AND(('Consolidated P&L'!G21+'Consolidated P&L'!G23)/'Consolidated P&L'!G11>=0.05,('Consolidated P&L'!G21+'Consolidated P&L'!G23)/'Consolidated P&L'!G11<=0.15),"OK","CHECK")) | H6: =IF('Consolidated P&L'!H11=0,"",IF(AND(('Consolidated P&L'!H21+'Consolidated P&L'!H23)/'Consolidated P&L'!H11>=0.05,('Consolidated P&L'!H21+'Consolidated P&L'!H23)/'Consolidated P&L'!H11<=0.15),"OK","CHECK")) | I6: =IF('Consolidated P&L'!I11=0,"",IF(AND(('Consolidated P&L'!I21+'Consolidated P&L'!I23)/'Consolidated P&L'!I11>=0.05,('Consolidated P&L'!I21+'Consolidated P&L'!I23)/'Consolidated P&L'!I11<=0.15),"OK","CHECK")) | J6: =IF('Consolidated P&L'!J11=0,"",IF(AND(('Consolidated P&L'!J21+'Consolidated P&L'!J23)/'Consolidated P&L'!J11>=0.05,('Consolidated P&L'!J21+'Consolidated P&L'!J23)/'Consolidated P&L'!J11<=0.15),"OK","CHECK")) | ... N6: =IF('Consolidated P&L'!N11=0,"",IF(AND(('Consolidated P&L'!N21+'Consolidated P&L'!N23)/'Consolidated P&L'!N11>=0.05,('Consolidated P&L'!N21+'Consolidated P&L'!N23)/'Consolidated P&L'!N11<=0.15),"OK","CHECK"))
A7: COGS entered when there are sales | B7: GMV > 0 but COGS blank | C7: =IF('Consolidated P&L'!C5=0,"",IF('Consolidated P&L'!C16=0,"CHECK","OK")) | D7: =IF('Consolidated P&L'!D5=0,"",IF('Consolidated P&L'!D16=0,"CHECK","OK")) | E7: =IF('Consolidated P&L'!E5=0,"",IF('Consolidated P&L'!E16=0,"CHECK","OK")) | F7: =IF('Consolidated P&L'!F5=0,"",IF('Consolidated P&L'!F16=0,"CHECK","OK")) | G7: =IF('Consolidated P&L'!G5=0,"",IF('Consolidated P&L'!G16=0,"CHECK","OK")) | H7: =IF('Consolidated P&L'!H5=0,"",IF('Consolidated P&L'!H16=0,"CHECK","OK")) | I7: =IF('Consolidated P&L'!I5=0,"",IF('Consolidated P&L'!I16=0,"CHECK","OK")) | J7: =IF('Consolidated P&L'!J5=0,"",IF('Consolidated P&L'!J16=0,"CHECK","OK")) | ... N7: =IF('Consolidated P&L'!N5=0,"",IF('Consolidated P&L'!N16=0,"CHECK","OK"))
A8: Marketing entered when there are sales | B8: GMV > 0 but no marketing anywhere | C8: =IF('Consolidated P&L'!C5=0,"",IF(('Consolidated P&L'!C29+'Consolidated P&L'!C32)=0,"CHECK","OK")) | D8: =IF('Consolidated P&L'!D5=0,"",IF(('Consolidated P&L'!D29+'Consolidated P&L'!D32)=0,"CHECK","OK")) | E8: =IF('Consolidated P&L'!E5=0,"",IF(('Consolidated P&L'!E29+'Consolidated P&L'!E32)=0,"CHECK","OK")) | F8: =IF('Consolidated P&L'!F5=0,"",IF(('Consolidated P&L'!F29+'Consolidated P&L'!F32)=0,"CHECK","OK")) | G8: =IF('Consolidated P&L'!G5=0,"",IF(('Consolidated P&L'!G29+'Consolidated P&L'!G32)=0,"CHECK","OK")) | H8: =IF('Consolidated P&L'!H5=0,"",IF(('Consolidated P&L'!H29+'Consolidated P&L'!H32)=0,"CHECK","OK")) | I8: =IF('Consolidated P&L'!I5=0,"",IF(('Consolidated P&L'!I29+'Consolidated P&L'!I32)=0,"CHECK","OK")) | J8: =IF('Consolidated P&L'!J5=0,"",IF(('Consolidated P&L'!J29+'Consolidated P&L'!J32)=0,"CHECK","OK")) | ... N8: =IF('Consolidated P&L'!N5=0,"",IF(('Consolidated P&L'!N29+'Consolidated P&L'!N32)=0,"CHECK","OK"))
A9: Blended RoAS above 1.0x | B9: Net sales ÷ all marketing ≥ 1.0 | C9: =IF(('Consolidated P&L'!C29+'Consolidated P&L'!C32)=0,"",IF('Consolidated P&L'!C11/('Consolidated P&L'!C29+'Consolidated P&L'!C32)>=1,"OK","CHECK")) | D9: =IF(('Consolidated P&L'!D29+'Consolidated P&L'!D32)=0,"",IF('Consolidated P&L'!D11/('Consolidated P&L'!D29+'Consolidated P&L'!D32)>=1,"OK","CHECK")) | E9: =IF(('Consolidated P&L'!E29+'Consolidated P&L'!E32)=0,"",IF('Consolidated P&L'!E11/('Consolidated P&L'!E29+'Consolidated P&L'!E32)>=1,"OK","CHECK")) | F9: =IF(('Consolidated P&L'!F29+'Consolidated P&L'!F32)=0,"",IF('Consolidated P&L'!F11/('Consolidated P&L'!F29+'Consolidated P&L'!F32)>=1,"OK","CHECK")) | G9: =IF(('Consolidated P&L'!G29+'Consolidated P&L'!G32)=0,"",IF('Consolidated P&L'!G11/('Consolidated P&L'!G29+'Consolidated P&L'!G32)>=1,"OK","CHECK")) | H9: =IF(('Consolidated P&L'!H29+'Consolidated P&L'!H32)=0,"",IF('Consolidated P&L'!H11/('Consolidated P&L'!H29+'Consolidated P&L'!H32)>=1,"OK","CHECK")) | I9: =IF(('Consolidated P&L'!I29+'Consolidated P&L'!I32)=0,"",IF('Consolidated P&L'!I11/('Consolidated P&L'!I29+'Consolidated P&L'!I32)>=1,"OK","CHECK")) | J9: =IF(('Consolidated P&L'!J29+'Consolidated P&L'!J32)=0,"",IF('Consolidated P&L'!J11/('Consolidated P&L'!J29+'Consolidated P&L'!J32)>=1,"OK","CHECK")) | ... N9: =IF(('Consolidated P&L'!N29+'Consolidated P&L'!N32)=0,"",IF('Consolidated P&L'!N11/('Consolidated P&L'!N29+'Consolidated P&L'!N32)>=1,"OK","CHECK"))
A10: CM1 not above gross margin | B10: Fulfilment costs entered | C10: =IF('Consolidated P&L'!C11=0,"",IF('Consolidated P&L'!C25<='Consolidated P&L'!C17,"OK","CHECK")) | D10: =IF('Consolidated P&L'!D11=0,"",IF('Consolidated P&L'!D25<='Consolidated P&L'!D17,"OK","CHECK")) | E10: =IF('Consolidated P&L'!E11=0,"",IF('Consolidated P&L'!E25<='Consolidated P&L'!E17,"OK","CHECK")) | F10: =IF('Consolidated P&L'!F11=0,"",IF('Consolidated P&L'!F25<='Consolidated P&L'!F17,"OK","CHECK")) | G10: =IF('Consolidated P&L'!G11=0,"",IF('Consolidated P&L'!G25<='Consolidated P&L'!G17,"OK","CHECK")) | H10: =IF('Consolidated P&L'!H11=0,"",IF('Consolidated P&L'!H25<='Consolidated P&L'!H17,"OK","CHECK")) | I10: =IF('Consolidated P&L'!I11=0,"",IF('Consolidated P&L'!I25<='Consolidated P&L'!I17,"OK","CHECK")) | J10: =IF('Consolidated P&L'!J11=0,"",IF('Consolidated P&L'!J25<='Consolidated P&L'!J17,"OK","CHECK")) | ... N10: =IF('Consolidated P&L'!N11=0,"",IF('Consolidated P&L'!N25<='Consolidated P&L'!N17,"OK","CHECK"))
A11: Fixed costs entered when there are sales | B11: People + tech + admin > 0 | C11: =IF('Consolidated P&L'!C5=0,"",IF(('Consolidated P&L'!C37+'Consolidated P&L'!C38+'Consolidated P&L'!C39)=0,"CHECK","OK")) | D11: =IF('Consolidated P&L'!D5=0,"",IF(('Consolidated P&L'!D37+'Consolidated P&L'!D38+'Consolidated P&L'!D39)=0,"CHECK","OK")) | E11: =IF('Consolidated P&L'!E5=0,"",IF(('Consolidated P&L'!E37+'Consolidated P&L'!E38+'Consolidated P&L'!E39)=0,"CHECK","OK")) | F11: =IF('Consolidated P&L'!F5=0,"",IF(('Consolidated P&L'!F37+'Consolidated P&L'!F38+'Consolidated P&L'!F39)=0,"CHECK","OK")) | G11: =IF('Consolidated P&L'!G5=0,"",IF(('Consolidated P&L'!G37+'Consolidated P&L'!G38+'Consolidated P&L'!G39)=0,"CHECK","OK")) | H11: =IF('Consolidated P&L'!H5=0,"",IF(('Consolidated P&L'!H37+'Consolidated P&L'!H38+'Consolidated P&L'!H39)=0,"CHECK","OK")) | I11: =IF('Consolidated P&L'!I5=0,"",IF(('Consolidated P&L'!I37+'Consolidated P&L'!I38+'Consolidated P&L'!I39)=0,"CHECK","OK")) | J11: =IF('Consolidated P&L'!J5=0,"",IF(('Consolidated P&L'!J37+'Consolidated P&L'!J38+'Consolidated P&L'!J39)=0,"CHECK","OK")) | ... N11: =IF('Consolidated P&L'!N5=0,"",IF(('Consolidated P&L'!N37+'Consolidated P&L'!N38+'Consolidated P&L'!N39)=0,"CHECK","OK"))
A12: Inventory days within band | B12: 30–150 days | C12: =IF('Cash & Working Capital'!C5=0,"",IF(AND('Cash & Working Capital'!C9>=30,'Cash & Working Capital'!C9<=150),"OK","CHECK")) | D12: =IF('Cash & Working Capital'!D5=0,"",IF(AND('Cash & Working Capital'!D9>=30,'Cash & Working Capital'!D9<=150),"OK","CHECK")) | E12: =IF('Cash & Working Capital'!E5=0,"",IF(AND('Cash & Working Capital'!E9>=30,'Cash & Working Capital'!E9<=150),"OK","CHECK")) | F12: =IF('Cash & Working Capital'!F5=0,"",IF(AND('Cash & Working Capital'!F9>=30,'Cash & Working Capital'!F9<=150),"OK","CHECK")) | G12: =IF('Cash & Working Capital'!G5=0,"",IF(AND('Cash & Working Capital'!G9>=30,'Cash & Working Capital'!G9<=150),"OK","CHECK")) | H12: =IF('Cash & Working Capital'!H5=0,"",IF(AND('Cash & Working Capital'!H9>=30,'Cash & Working Capital'!H9<=150),"OK","CHECK")) | I12: =IF('Cash & Working Capital'!I5=0,"",IF(AND('Cash & Working Capital'!I9>=30,'Cash & Working Capital'!I9<=150),"OK","CHECK")) | J12: =IF('Cash & Working Capital'!J5=0,"",IF(AND('Cash & Working Capital'!J9>=30,'Cash & Working Capital'!J9<=150),"OK","CHECK")) | ... N12: =IF('Cash & Working Capital'!N5=0,"",IF(AND('Cash & Working Capital'!N9>=30,'Cash & Working Capital'!N9<=150),"OK","CHECK"))
A13: Receivable days within band | B13: 0–60 days | C13: =IF('Cash & Working Capital'!C6=0,"",IF(AND('Cash & Working Capital'!C10>=0,'Cash & Working Capital'!C10<=60),"OK","CHECK")) | D13: =IF('Cash & Working Capital'!D6=0,"",IF(AND('Cash & Working Capital'!D10>=0,'Cash & Working Capital'!D10<=60),"OK","CHECK")) | E13: =IF('Cash & Working Capital'!E6=0,"",IF(AND('Cash & Working Capital'!E10>=0,'Cash & Working Capital'!E10<=60),"OK","CHECK")) | F13: =IF('Cash & Working Capital'!F6=0,"",IF(AND('Cash & Working Capital'!F10>=0,'Cash & Working Capital'!F10<=60),"OK","CHECK")) | G13: =IF('Cash & Working Capital'!G6=0,"",IF(AND('Cash & Working Capital'!G10>=0,'Cash & Working Capital'!G10<=60),"OK","CHECK")) | H13: =IF('Cash & Working Capital'!H6=0,"",IF(AND('Cash & Working Capital'!H10>=0,'Cash & Working Capital'!H10<=60),"OK","CHECK")) | I13: =IF('Cash & Working Capital'!I6=0,"",IF(AND('Cash & Working Capital'!I10>=0,'Cash & Working Capital'!I10<=60),"OK","CHECK")) | J13: =IF('Cash & Working Capital'!J6=0,"",IF(AND('Cash & Working Capital'!J10>=0,'Cash & Working Capital'!J10<=60),"OK","CHECK")) | ... N13: =IF('Cash & Working Capital'!N6=0,"",IF(AND('Cash & Working Capital'!N10>=0,'Cash & Working Capital'!N10<=60),"OK","CHECK"))
A14: Working capital entered | B14: Inventory or receivables filled when there are sales | C14: =IF('Consolidated P&L'!C5=0,"",IF(('Cash & Working Capital'!C5+'Cash & Working Capital'!C6)=0,"CHECK","OK")) | D14: =IF('Consolidated P&L'!D5=0,"",IF(('Cash & Working Capital'!D5+'Cash & Working Capital'!D6)=0,"CHECK","OK")) | E14: =IF('Consolidated P&L'!E5=0,"",IF(('Cash & Working Capital'!E5+'Cash & Working Capital'!E6)=0,"CHECK","OK")) | F14: =IF('Consolidated P&L'!F5=0,"",IF(('Cash & Working Capital'!F5+'Cash & Working Capital'!F6)=0,"CHECK","OK")) | G14: =IF('Consolidated P&L'!G5=0,"",IF(('Cash & Working Capital'!G5+'Cash & Working Capital'!G6)=0,"CHECK","OK")) | H14: =IF('Consolidated P&L'!H5=0,"",IF(('Cash & Working Capital'!H5+'Cash & Working Capital'!H6)=0,"CHECK","OK")) | I14: =IF('Consolidated P&L'!I5=0,"",IF(('Cash & Working Capital'!I5+'Cash & Working Capital'!I6)=0,"CHECK","OK")) | J14: =IF('Consolidated P&L'!J5=0,"",IF(('Cash & Working Capital'!J5+'Cash & Working Capital'!J6)=0,"CHECK","OK")) | ... N14: =IF('Consolidated P&L'!N5=0,"",IF(('Cash & Working Capital'!N5+'Cash & Working Capital'!N6)=0,"CHECK","OK"))
A15: Cash roll-forward populated | B15: Opening cash present | C15: =IF('Consolidated P&L'!C5=0,"",IF('Cash & Working Capital'!C15=0,"CHECK","OK")) | D15: =IF('Consolidated P&L'!D5=0,"",IF('Cash & Working Capital'!D15=0,"CHECK","OK")) | E15: =IF('Consolidated P&L'!E5=0,"",IF('Cash & Working Capital'!E15=0,"CHECK","OK")) | F15: =IF('Consolidated P&L'!F5=0,"",IF('Cash & Working Capital'!F15=0,"CHECK","OK")) | G15: =IF('Consolidated P&L'!G5=0,"",IF('Cash & Working Capital'!G15=0,"CHECK","OK")) | H15: =IF('Consolidated P&L'!H5=0,"",IF('Cash & Working Capital'!H15=0,"CHECK","OK")) | I15: =IF('Consolidated P&L'!I5=0,"",IF('Cash & Working Capital'!I15=0,"CHECK","OK")) | J15: =IF('Consolidated P&L'!J5=0,"",IF('Cash & Working Capital'!J15=0,"CHECK","OK")) | ... N15: =IF('Consolidated P&L'!N5=0,"",IF('Cash & Working Capital'!N15=0,"CHECK","OK"))

Sheet Definitions
A1: Definitions — every line, what it means, where to find it, and the common mistake
A3: Tab | B3: Block | C3: Line | D3: What it is | E3: Where to find it | F3: Common mistake
A4: Website | B4: REVENUE | C4: Gross sales (GMV) incl. GST | D4: Everything customers ordered and you shipped this month, valued at the price they paid before any discount, including GST. | E4: Shopify › Analytics › Gross sales (before discounts, returns and shipping). Woo/Magento: sum of order value incl. GST. | F4: Entering Shopify 'Total sales' (already net of discounts and returns) or entering values excluding GST. Enter the gross, GST-inclusive number and let the sheet deduct.
A5: Website | B5: REVENUE | C5: Consumer discounts & coupons | D5: Discounts the shopper saw at checkout: coupon codes, automatic discounts, sale price-offs. Funded by you. | E5: Shopify › Analytics › Discounts. | F5: Mixing platform commission in here. Commission is what the platform keeps; discounts are what the customer did not pay.
A6: Website | B6: REVENUE | C6: Returns, RTO & cancellations after dispatch | D6: Value (at selling price incl. GST) of orders that came back: undelivered COD (RTO), customer returns, cancellations after dispatch. | E6: Shopify › Analytics › Returns, plus RTO value from your courier or Shiprocket RTO report. | F6: Counting only refunds. RTO on COD orders is the bigger number for most website channels and never shows as a refund.
A7: Website | B7: REVENUE | C7: Net revenue before GST | D7: What is left after discounts, partner margin and returns. Still includes GST.
A8: Website | B8: REVENUE | C8: Less: GST (output tax) | D8: GST collected on your net revenue, at the rate set on Start Here for this channel. Overwrite with your GSTR-1 figure if you have it. | F8: Deducting GST as a percentage of the gross number instead of backing it out (÷ 1.18, not × 0.18).
A9: Website | B9: REVENUE | C9: NET SALES (post GST) | D9: The number every ratio below is measured against. Investors call it net sales, NSR or NMV.
A10: Website | B10: COST OF GOODS | C10: Cost of goods sold (product + conversion + primary packaging) | D10: The cost of the units you actually sold: product, manufacturing or job-work, and the packaging that touches the product. | E10: Contract-manufactured: product cost + primary packaging per unit × units sold this month. Include the cost of testers and samples given away. | F10: Entering this month's purchases or factory bills. Purchases go to inventory; COGS is only what left the warehouse as sales. Secondary packaging (shippers, fillers) goes in Logistics.
A11: Website | B11: COST OF GOODS | C11: GROSS MARGIN | D11: Net sales less cost of goods. The first number an investor looks at.
A12: Website | B12: FULFILMENT & CHANNEL COSTS | C12: Logistics: forward, reverse, RTO & COD charges, secondary packaging | D12: Getting product to the customer and back: courier, 3PL pick-pack, RTO charges, COD collection fee, shipping cartons. | E12: Shiprocket / Delhivery / Bluedart invoices for the month excl. GST, plus shipper cartons and fillers. Amazon: FBA fulfilment fee. | F12: Leaving out reverse and RTO charges, which can be 30–50% of forward cost in COD-heavy or apparel businesses.
A13: Website | B13: FULFILMENT & CHANNEL COSTS | C13: Less: shipping & COD fees collected from customers | D13: Fees customers paid you for delivery or COD, netted against logistics. | E13: Shopify › Analytics › Shipping charges, plus COD handling fees charged to customers. Enter as a positive number; the sheet subtracts it. | F13: Entering it as a negative. Enter positive; the formula subtracts.
A14: Website | B14: FULFILMENT & CHANNEL COSTS | C14: Warehousing & operations (rent, staff, packing labour) | D14: Cost of storing and handling stock, before it ships. | E14: Warehouse rent, warehouse staff, packing consumables for the month. If shared across channels, split by orders. | F14: Putting warehouse staff under Salaries. They scale with orders, so they belong here.
A15: Website | B15: FULFILMENT & CHANNEL COSTS | C15: Payment gateway charges | D15: What the gateway kept from prepaid collections. | E15: Razorpay / PayU / Cashfree statement › fees for the month excl. GST. Typically 1.8–2.2% of prepaid collections. | F15: Ignoring it because the payout arrives net. Gross up collections and show the fee.
A16: Website | B16: FULFILMENT & CHANNEL COSTS | C16: CONTRIBUTION MARGIN 1 (CM1) | D16: Margin after getting the product to the customer and paying the channel. What is left to pay for marketing.
A17: Website | B17: MARKETING & SELLING | C17: Performance marketing (Meta, Google, affiliates) | D17: Paid media and channel advertising that drives this channel's sales this month, excluding GST (you claim the input credit). | E17: Meta Ads Manager and Google Ads billing for the month, excluding GST. Add affiliate and influencer payouts tied to sales. | F17: Entering the GST-inclusive invoice. Also: agency retainers and content production are brand costs on the Consolidated tab, not here.
A18: Website | B18: MARKETING & SELLING | C18: CONTRIBUTION MARGIN 2 (CM2) | D18: Margin after channel-level marketing and selling costs. Positive CM2 means the channel pays for its own growth.
A19: Website | B19: MEMO | C19: Orders shipped (count) | D19: Number of orders that went out. Used for AOV. | E19: Shopify › Orders (fulfilled) or marketplace › Orders shipped. Offline / Qcom: units or cases invoiced. | F19: Counting orders placed rather than shipped; cancellations inflate it.
A20: Website | B20: MEMO | C20: Average order value incl. GST | D20: GMV per shipped order.
A21: Website | B21: MEMO | C21: RoAS (net sales ÷ marketing) | D21: Net sales generated per rupee of marketing in this channel. Below 1.5× on a website channel is a red flag unless the brand is very new.
A22: Quick Commerce | B22: REVENUE | C22: Gross sales (GMV) incl. GST | D22: Everything customers ordered and you shipped this month, valued at the price they paid before any discount, including GST. | E22: Partner dashboard › GMV at MRP incl. GST for the month. | F22: Entering Shopify 'Total sales' (already net of discounts and returns) or entering values excluding GST. Enter the gross, GST-inclusive number and let the sheet deduct.
A23: Quick Commerce | B23: REVENUE | C23: Consumer discounts & coupons | D23: Discounts the shopper saw at checkout: coupon codes, automatic discounts, sale price-offs. Funded by you. | E23: Leave blank here if you enter brand-funded promos on the Consumer promotions line. | F23: Mixing platform commission in here. Commission is what the platform keeps; discounts are what the customer did not pay.
A24: Quick Commerce | B24: REVENUE | C24: Quick-commerce partner margin | D24: The partner's margin when they buy your stock or raise a purchase order: MRP less what you invoice them. | E24: MRP less your invoice price to the partner, per the trade agreement (typically 25–40%). | F24: Forgetting this line makes GM% look like a website channel. If your invoice already excludes it, GMV must be grossed up to MRP or the line stays zero.
A25: Quick Commerce | B25: REVENUE | C25: Returns, RTO & cancellations after dispatch | D25: Value (at selling price incl. GST) of orders that came back: undelivered COD (RTO), customer returns, cancellations after dispatch. | E25: Expiry or damage returns reversed on the PO. Usually near zero. | F25: Counting only refunds. RTO on COD orders is the bigger number for most website channels and never shows as a refund.
A26: Quick Commerce | B26: REVENUE | C26: Net revenue before GST | D26: What is left after discounts, partner margin and returns. Still includes GST.
A27: Quick Commerce | B27: REVENUE | C27: Less: GST (output tax) | D27: GST collected on your net revenue, at the rate set on Start Here for this channel. Overwrite with your GSTR-1 figure if you have it. | F27: Deducting GST as a percentage of the gross number instead of backing it out (÷ 1.18, not × 0.18).
A28: Quick Commerce | B28: REVENUE | C28: NET SALES (post GST) | D28: The number every ratio below is measured against. Investors call it net sales, NSR or NMV.
A29: Quick Commerce | B29: REVENUE | C29: Consumer promotions funded by brand | D29: Price-offs the shopper sees on the quick-commerce app that you fund, per the partner's debit note. | E29: Partner's debit note for brand-funded discounts, or dashboard › Promotions › brand share. | F29: Leaving it inside 'discounts' when the partner also funds part of the promo. Enter only your share.
A30: Quick Commerce | B30: REVENUE | C30: Net sales after brand-funded promotions | D30: Net sales after the promotions you fund. Gross margin is measured from here.
